<?xml version="1.0"?>
<robot xmlns:xacro="http://www.ros.org/wiki/xacro" name="anhc_bot">
  <xacro:property name="chassis_length" value="0.8"/>
  <xacro:property name="chassis_width"  value="0.8"/>
  <xacro:property name="chassis_height" value="0.6"/>
  <xacro:property name="wheel_radius"   value="0.08"/>
  <xacro:property name="wheel_width"    value="0.08"/>
  <xacro:property name="wheel_x" value="0.15"/>
  <xacro:property name="wheel_y" value="0.21"/>
  <xacro:property name="chassis_mass" value="20.0"/>
  <xacro:property name="wheel_mass" value="1.2"/>

  <link name="base_footprint"/>

  <link name="base_link">
    <inertial>
      <origin xyz="0 0 0" rpy="0 0 0"/>
      <mass value="${chassis_mass}"/>
      <inertia ixx="0.433" ixy="0.0" ixz="0.0" iyy="0.563" iyz="0.0" izz="0.683"/>
    </inertial>
    <!-- OBJ from Blender in metres; scale = 1 1 1. MTL auto-loaded by matching base name. -->
    <!-- xyz offsets the mesh so its geometric centre aligns with the base_link frame origin. -->
    <visual>
      <origin xyz="0.9 0 0.06" rpy="1.5708 0 0"/>
      <geometry>
        <mesh filename="package://anhc_description/meshes/anhc_botrl/visual/obj/baselink.obj"
              scale="1 1 1"/>
      </geometry>
    </visual>
    <collision>
      <origin xyz="0 0 ${chassis_height/2.0}" rpy="0 0 0"/>
      <geometry>
        <box size="${chassis_length} ${chassis_width} ${chassis_height}"/>
      </geometry>
    </collision>
  </link>

  <joint name="base_footprint_joint" type="fixed">
    <parent link="base_footprint"/>
    <child link="base_link"/>
    <origin xyz="0 0 0" rpy="0 0 0"/>
  </joint>

  <!-- Primitive wheel model (no external OBJ dependency). -->
  <xacro:macro name="wheel_link" params="name x y">
    <link name="${name}">
      <inertial>
        <origin xyz="0 0 0" rpy="0 0 0"/>
        <mass value="${wheel_mass}"/>
        <inertia ixx="0.0022" ixy="0.0" ixz="0.0" iyy="0.0040" iyz="0.0" izz="0.0022"/>
      </inertial>
      <visual>
        <origin xyz="0 0 0" rpy="1.5708 0 0"/>
        <geometry>
          <cylinder radius="${wheel_radius}" length="${wheel_width}"/>
        </geometry>
        <material name="wheel_dark_gray">
          <color rgba="0.10 0.10 0.10 1.0"/>
        </material>
      </visual>
      <collision>
        <origin xyz="0 0 0" rpy="1.5708 0 0"/>
        <geometry>
          <cylinder radius="${wheel_radius}" length="${wheel_width}"/>
        </geometry>
      </collision>
    </link>
    <joint name="${name}_joint" type="continuous">
      <parent link="base_link"/>
      <child link="${name}"/>
      <origin xyz="${x} ${y} ${wheel_radius}" rpy="0 0 0"/>
      <axis xyz="0 1 0"/>
      <limit effort="50.0" velocity="30.0"/>
      <dynamics damping="0.5" friction="0.2"/>
    </joint>
  </xacro:macro>

  <!-- Front wheels (powered, drive wheels) -->
  <xacro:wheel_link name="front_left_wheel"  x="${wheel_x}"                    y="${wheel_y}"/>
  <xacro:wheel_link name="front_right_wheel" x="${wheel_x}"                    y="-${wheel_y}"/>

  <!-- Rear wheels — same joint type (continuous), driven passively via physics -->
  <xacro:wheel_link name="back_left_wheel"   x="-${chassis_length/2.0 - 0.05}" y="${wheel_y}"/>
  <xacro:wheel_link name="back_right_wheel"  x="-${chassis_length/2.0 - 0.05}" y="-${wheel_y}"/>

  <link name="lidar_link">
    <inertial>
      <origin xyz="0 0 0" rpy="0 0 0"/>
      <mass value="0.25"/>
      <inertia ixx="0.0004" ixy="0.0" ixz="0.0" iyy="0.0004" iyz="0.0" izz="0.0005"/>
    </inertial>
    <!-- OBJ from Blender in metres; scale = 1 1 1. MTL auto-loaded by matching base name. -->
    <visual>
      <origin xyz="0.0132 0.0205 0.0000" rpy="1.5708 0 3.14159"/>
      <geometry>
        <mesh filename="package://anhc_description/meshes/anhc_botrl/visual/obj/lidar.obj"
              scale="1 1 1"/>
      </geometry>
    </visual>
    <!-- No collision: avoid spurious contacts with world mesh; lidar is not physical. -->
  </link>
  <joint name="lidar_joint" type="fixed">
    <parent link="base_link"/>
    <child link="lidar_link"/>
    <!-- Put LiDAR scan plane clearly above chassis top (0.6 m) to avoid self-hits. -->
    <origin xyz="0.1 0 0.4" rpy="0 0 0"/>
  </joint>

  <link name="camera_link">
    <inertial>
      <origin xyz="0 0 0" rpy="0 0 0"/>
      <mass value="0.35"/>
      <inertia ixx="0.0009" ixy="0.0" ixz="0.0" iyy="0.0010" iyz="0.0" izz="0.0008"/>
    </inertial>
    <!-- OBJ from Blender in metres; scale = 1 1 1. MTL auto-loaded by matching base name. -->
    <visual>
      <origin xyz="0.0133 0.0128 0.0000" rpy="1.5708 0 0"/>
      <geometry>
        <mesh filename="package://anhc_description/meshes/anhc_botrl/visual/obj/camera.obj"
              scale="1 1 1"/>
      </geometry>
    </visual>
    <collision>
      <origin xyz="0 0 0" rpy="0 0 0"/>
      <geometry><box size="0.08 0.06 0.05"/></geometry>
    </collision>
  </link>
  <joint name="camera_joint" type="fixed">
    <parent link="base_link"/>
    <child link="camera_link"/>
    <origin xyz="0.22 0 0.7" rpy="0 0 0"/>
  </joint>

  <link name="imu_link">
    <inertial>
      <origin xyz="0 0 0" rpy="0 0 0"/>
      <mass value="0.1"/>
      <inertia ixx="0.0001" ixy="0.0" ixz="0.0" iyy="0.0001" iyz="0.0" izz="0.0001"/>
    </inertial>
  </link>
  <joint name="imu_joint" type="fixed">
    <parent link="base_link"/>
    <child link="imu_link"/>
    <origin xyz="0 0 0.125" rpy="0 0 0"/>
  </joint>

  <xacro:include filename="$(find anhc_description)/urdf/anhc_bot.gazebo.xacro"/>
</robot>
