<?xml version="1.0"?>
<robot xmlns:xacro="http://www.ros.org/wiki/xacro" name="anhc_bot">
  <xacro:property name="chassis_length" value="0.5"/>
  <xacro:property name="chassis_width" value="0.4"/>
  <xacro:property name="chassis_height" value="0.25"/>
  <xacro:property name="wheel_radius" value="0.08"/>
  <xacro:property name="wheel_width" value="0.04"/>
  <xacro:property name="wheel_x" value="0.15"/>
  <xacro:property name="wheel_y" value="0.21"/>
  <xacro:property name="chassis_mass" value="20.0"/>
  <xacro:property name="wheel_mass" value="1.2"/>
  <xacro:property name="caster_mass" value="0.5"/>

  <link name="base_footprint"/>

  <link name="base_link">
    <inertial>
      <origin xyz="0 0 0" rpy="0 0 0"/>
      <mass value="${chassis_mass}"/>
      <inertia ixx="0.433" ixy="0.0" ixz="0.0" iyy="0.563" iyz="0.0" izz="0.683"/>
    </inertial>
    <visual>
      <origin xyz="0 0 ${chassis_height/2.0}" rpy="0 0 0"/>
      <geometry>
        <box size="${chassis_length} ${chassis_width} ${chassis_height}"/>
      </geometry>
      <material name="dark_gray">
        <color rgba="0.25 0.25 0.28 1.0"/>
      </material>
    </visual>
    <collision>
      <origin xyz="0 0 ${chassis_height/2.0}" rpy="0 0 0"/>
      <geometry>
        <box size="${chassis_length} ${chassis_width} ${chassis_height}"/>
      </geometry>
    </collision>
  </link>

  <joint name="base_footprint_joint" type="fixed">
    <parent link="base_footprint"/>
    <child link="base_link"/>
    <origin xyz="0 0 0" rpy="0 0 0"/>
  </joint>

  <xacro:macro name="wheel_link" params="name x y">
    <link name="${name}">
      <inertial>
        <origin xyz="0 0 0" rpy="0 0 0"/>
        <mass value="${wheel_mass}"/>
        <inertia ixx="0.0022" ixy="0.0" ixz="0.0" iyy="0.0040" iyz="0.0" izz="0.0022"/>
      </inertial>
      <visual>
        <origin xyz="0 0 0" rpy="1.5708 0 0"/>
        <geometry>
          <cylinder radius="${wheel_radius}" length="${wheel_width}"/>
        </geometry>
        <material name="black">
          <color rgba="0.05 0.05 0.05 1.0"/>
        </material>
      </visual>
      <collision>
        <origin xyz="0 0 0" rpy="1.5708 0 0"/>
        <geometry>
          <cylinder radius="${wheel_radius}" length="${wheel_width}"/>
        </geometry>
      </collision>
    </link>
    <joint name="${name}_joint" type="continuous">
      <parent link="base_link"/>
      <child link="${name}"/>
      <origin xyz="${x} ${y} ${wheel_radius}" rpy="0 0 0"/>
      <axis xyz="0 1 0"/>
      <limit effort="50.0" velocity="30.0"/>
      <dynamics damping="0.5" friction="0.2"/>
    </joint>
  </xacro:macro>

  <xacro:wheel_link name="left_wheel" x="${wheel_x}" y="${wheel_y}"/>
  <xacro:wheel_link name="right_wheel" x="${wheel_x}" y="-${wheel_y}"/>

  <xacro:macro name="caster_wheel" params="name x y">
    <link name="${name}">
      <inertial>
        <origin xyz="0 0 0" rpy="0 0 0"/>
        <mass value="${caster_mass}"/>
        <inertia ixx="0.0007" ixy="0.0" ixz="0.0" iyy="0.0009" iyz="0.0" izz="0.0007"/>
      </inertial>
      <visual>
        <origin xyz="0 0 0" rpy="1.5708 0 0"/>
        <geometry>
          <sphere radius="0.04"/>
        </geometry>
        <material name="silver">
          <color rgba="0.7 0.7 0.75 1.0"/>
        </material>
      </visual>
      <collision>
        <origin xyz="0 0 0" rpy="0 0 0"/>
        <geometry>
          <sphere radius="0.04"/>
        </geometry>
      </collision>
    </link>
    <joint name="${name}_joint" type="fixed">
      <parent link="base_link"/>
      <child link="${name}"/>
      <origin xyz="${x} ${y} 0.04" rpy="0 0 0"/>
    </joint>
  </xacro:macro>

  <xacro:caster_wheel name="rear_left_caster" x="-0.18" y="0.16"/>
  <xacro:caster_wheel name="rear_right_caster" x="-0.18" y="-0.16"/>

  <link name="lidar_link">
    <inertial>
      <origin xyz="0 0 0" rpy="0 0 0"/>
      <mass value="0.25"/>
      <inertia ixx="0.0004" ixy="0.0" ixz="0.0" iyy="0.0004" iyz="0.0" izz="0.0005"/>
    </inertial>
    <visual>
      <origin xyz="0 0 0" rpy="0 0 0"/>
      <geometry><cylinder radius="0.04" length="0.05"/></geometry>
      <material name="blue"><color rgba="0.2 0.2 0.9 1.0"/></material>
    </visual>
    <collision>
      <origin xyz="0 0 0" rpy="0 0 0"/>
      <geometry><cylinder radius="0.04" length="0.05"/></geometry>
    </collision>
  </link>
  <joint name="lidar_joint" type="fixed">
    <parent link="base_link"/>
    <child link="lidar_link"/>
    <origin xyz="0 0 0.30" rpy="0 0 0"/>
  </joint>

  <link name="camera_link">
    <inertial>
      <origin xyz="0 0 0" rpy="0 0 0"/>
      <mass value="0.35"/>
      <inertia ixx="0.0009" ixy="0.0" ixz="0.0" iyy="0.0010" iyz="0.0" izz="0.0008"/>
    </inertial>
    <visual>
      <origin xyz="0 0 0" rpy="0 0 0"/>
      <geometry><box size="0.08 0.06 0.05"/></geometry>
      <material name="navy"><color rgba="0.1 0.1 0.5 1.0"/></material>
    </visual>
    <collision>
      <origin xyz="0 0 0" rpy="0 0 0"/>
      <geometry><box size="0.08 0.06 0.05"/></geometry>
    </collision>
  </link>
  <joint name="camera_joint" type="fixed">
    <parent link="base_link"/>
    <child link="camera_link"/>
    <origin xyz="0.22 0 0.20" rpy="0 0.1745 0"/>
  </joint>

  <link name="imu_link">
    <inertial>
      <origin xyz="0 0 0" rpy="0 0 0"/>
      <mass value="0.1"/>
      <inertia ixx="0.0001" ixy="0.0" ixz="0.0" iyy="0.0001" iyz="0.0" izz="0.0001"/>
    </inertial>
  </link>
  <joint name="imu_joint" type="fixed">
    <parent link="base_link"/>
    <child link="imu_link"/>
    <origin xyz="0 0 0.125" rpy="0 0 0"/>
  </joint>

  <xacro:include filename="$(find anhc_description)/urdf/anhc_bot.gazebo.xacro"/>
</robot>
